Workbook

Sheet Title
A1: MMS Fehlercodeliste / Alarmliste - Namen || ECS Error Code List - Names
A3: Description | B3: This list contains all error codes that may occur in any system variant of any EngineControlSystem (ECS). This includes the ECS devices ECU7, ECU8, ECU9 Diesel, ECU9 Gas, EXU_ESD, EXU_EMU9, EXU_CPM, SXU. Any such device and software may only set a subset of these error codes.
A4: Reference Documents
A5: Document Specific Configuration Attributes | B5: Configuration-ID: Entwicklungsphase: Konfigurationsklasse: K-Steuerungsgrad: Vertraulichkeitsgrad: Dokument-Eigner: | C5: TDC/MMS-001/21 Dokument Uwe Kunkel
A6: Revision History
A7: Issue No. | B7: Changes, Remarks | D7: Author | E7: Date | F7: Reference
A8: 0.1 | B8: first version under configmanagement. State 18.12.2020 | D8: Uwe Kunkel | E8: 44253
A9: 0.2 | B9: Config-ID corrected. New Alarms 1990 - 2007 added, SPN/FMI information updated | D9: Uwe Kunkel | E9: 44259
A10: 0.3 | B10: Incorporate ECU9_Diesel_Rail CR 1335225 | D10: Uwe Kunkel | E10: 44438 | F10: WI_1317393
A11: 0.4 | B11: Correct FMI of Alarms 1877 and 1878 and SPN of Alarm 1987 missed in last update | D11: Uwe Kunkel | E11: 44456 | F11: WI_1317393
A12: 0.5 | B12: Added new ECU Alarms 2017 to 2026, changed Name of 1591, added DTC to 986 | D12: Uwe Kunkel | E12: 44547 | F12: WI_1495780
A13: 0.6 | B13: Added new ECU Alarms 2027 and 2028. Corrected typo in SPN for Alarm 2014 | D13: Uwe Kunkel | E13: 44581 | F13: WI_1500612
A14: 0.7 | B14: Corrected FMI of alarm 1371 to match 1370 | D14: Uwe Kunkel | E14: 44222 | F14: CR_1536623
A15: 0.8 | B15: Added DTC for Alarms 518, 995, 1587, 2017, 2029 and 2030. Added Alarms 518, 2029 and 2030 | D15: Uwe Kunkel | E15: 44854 | F15: CR_1548356
A16: 0.9 | B16: Added Alarms 516, 591, 592, 1995, 1998, 1999, 2031 - 2054 (mainly Treefrog) | D16: Uwe Kunkel | E16: 44875
A17: 0.10 | B17: Added DTCs for Alarms of 0.9 Added SPN search tab. Added Bitcoded Alarminformation with SPN/FMI and extended the Failure Code search to display all additional information. AKM alarms (from 9000) added ESD and EMU9 DTCs updated Corrected Bitnumbering for Alarms 1884ff | D17: Uwe Kunkel | E17: 44902
A18: 0.11 | B18: Added Alarms 2056 (Gas/AKM) and 2057 (Treefrog) | D18: Uwe Kunkel | E18: 44944
A19: 0.12 | B19: Added Alarms 2059 - 2064 (Gas) | D19: Uwe Kunkel | E19: 44949
A20: 0.13 | B20: Correct SPN of alarm 2053 | D20: Uwe Kunkel | E20: 44953
A21: 0.14 | B21: Updated SPN/FMI after J1939 board. Proprietary SPNs for Alarms 591, 592, 2031, 2034 and 2035 pending. Blue markings for changes since 0.8 | D21: Uwe Kunkel | E21: 44958
A22: 0.15 | B22: Fix Description of alarm 1800. Blue markings for changes since 0.8 | D22: Uwe Kunkel | E22: 44964
A23: 0.16 | B23: Update Alarms 2056, 2060, 2061, 2062 and 2064 | D23: Uwe Kunkel | E23: 45006
A24: 0.17 | B24: Added Alarms 2065 - 2070 | D24: Uwe Kunkel | E24: 45058
A25: 0.18 | B25: Changed SPN of Alarms 730, 1473 and 1474 to standard for Dolphin, Corrected FMI of Alarm 729 and 1743 (Dolphin) Added SPN/FMI of Alarms 1694, 2058, 1059 and 2063 (ECU9Gas) | D25: Uwe Kunkel | E25: 45106 | F25: CR_1610748
A26: 0.19 | B26: Changed FMI of 1743 back to 0, as the three-level alarm is for GO only and handled by the LOP | D26: Uwe Kunkel | E26: 45118
A27: 0.20 | B27: Add SPN/FMI to Alarm 1764, added Alarm 2071 (ECU9Gas) | D27: Uwe Kunkel | E27: 45120
A28: 0.21 | B28: Add Alarm-PV to alarms 478 and 479 | D28: Uwe Kunkel | E28: 45169 | F28: CR_2353132
A29: 0.22 | B29: Add new alarms for Dachshund, Antelope and Gas (2072 - 2120) | D29: Uwe Kunkel | E29: 45307
A30: 0.23 | B30: Added more new alarms (2021 - 2030) | D30: Uwe Kunkel | E30: 45362
A31: 0.24 | B31: Add new alarms for Dachshund (2131 - 2134) and missing EMU9 alarms. Removed EMU Alarms 6800ff (Never used and removed from EDW) Blue markings for changes since 0.21 | D31: Uwe Kunkel | E31: 45390
A32: 0.25 | B32: Add new alarms for Dachshund and Gas (2135 - 2153). Blue markings for changes since 0.21 Add SPN/FMI for EMU9 alarms | D32: Uwe Kunkel | E32: 45502
A33: 0.26 | B33: Removed ECU Alarms 2103, 2104, 2131, 2132 and 2133. Alarms already existed and are used instead (220, 1003, 419, 434 and 435) | D33: Uwe Kunkel | E33: 45517 | F33: CR_3776020
A34: 0.27 | B34: Add new EIM Alarms 8038 - 8044 | D34: Uwe Kunkel | E34: 45524
A35: 0.28 | B35: Add missing AKM alarms: 9050, 9051, 9151, 9152, 9171-9190, 9428, 9429 Add new ECU4 obsolescence alarms 537 (506 has a changed name in v2) Add SPN/FMI information for ECU9 Gas Add new Dolphin SP2 alarms Add new Bluewhale alarms for EGAT Monitoring Add new ECU9 Retrofit Alarme | D35: Uwe Kunkel | E35: 45763
A36: 0.29 | B36: Add missing alarms 2166 and 2195 | D36: Uwe Kunkel | E36: 45849
A37: 0.30 | B37: Add missing ECU4 Retrofit alarms 198 and 199 | D37: Uwe Kunkel | E37: 45968
A38: 0.31 | B38: Add new Alarms 2196 - 2200 (Pollux), 2201 (LargeEngine) and 2202 (2.8 SP5) | D38: Uwe Kunkel | E38: 45980

Sheet MMS Alarms - Names
A1: MMS Fehlercodeliste / Alarmliste - Namen || ECS Error Code List - Names
A2: Diese Liste enthält alle Alarme, die in einer jeden Variante eines MotorManagementSystems (MMS) auftreten können. Dies beinhaltet die Steuergeräte ECU7, ECU8, ECU9 Diesel, ECU9 Gas, EXU_ESD, EXU_EMU9, EXU_CPM, SXU. Jede Gerät für sich mit ihrer Software kann nur einen Teil dieser Alarme erzeugen.
A3: This list contains all error codes that may occur in any system variant of any EngineControlSystem (ECS). This includes the ECS devices ECU7, ECU8, ECU9 Diesel, ECU9 Gas, EXU_ESD, EXU_EMU9, EXU_CPM, SXU. Any such device and software may only set a subset of these error codes.
D4: Changes are marked blue | E4: Datum / Date see Title page
A5: Alarm Nr. / Error Code | B5: Parameter z.k.p.-Nr. | C5: PV z.k.p.-Nr. | D5: Name (English) | E5: Name (Deutsch) | F5: J1939 SPN | G5: J1939 FMI | H5: Auslösenden Funktion / triggerin function | I5: Comment
A6: 3 | B6: 2.0122.931 | C6: 2.0122.911 | D6: HI T-Fuel | E6: HI T-Kraftstoff | F6: 174 | G6: 15 | H6: Messstellen_Mon_Prot_Neu_AbFSW_2_4_ECU9
A7: 4 | B7: 2.0122.932 | C7: 2.0122.912 | D7: SS T-Fuel | E7: SS T-Kraftstoff | F7: 174 | G7: 0 | H7: Messstellen_Mon_Prot_Neu_AbFSW_2_4_ECU9
A8: 5 | B8: 2.0121.931 | C8: 2.0121.911 | D8: HI T-Charge Air | E8: HI T-Ladeluft | F8: 105 | G8: 15 | H8: Messstellen_Mon_Prot_Neu_AbFSW_2_4_ECU9
A9: 6 | B9: 2.0121.932 | C9: 2.0121.912 | D9: SS T-Charge Air | E9: SS T-Ladeluft | F9: 105 | G9: 0 | H9: Messstellen_Mon_Prot_Neu_AbFSW_2_4_ECU9
A10: 9 | B10: 2.0124.931 | C10: 2.0124.911 | D10: HI T-Coolant Intercooler | E10: HI T-Kuehlmittel Intercooler | F10: 52 | G10: 15 | H10: Messstellen_Mon_Prot_Neu_AbFSW_2_4_ECU9
A11: 10 | B11: 2.0124.932 | C11: 2.0124.912 | D11: SS T-Coolant Intercooler | E11: SS T-Kuehlmittel Intercooler | F11: 52 | G11: 0 | H11: Messstellen_Mon_Prot_Neu_AbFSW_2_4_ECU9
A12: 15 | B12: 2.0100.921 | C12: 2.0100.901 | D12: LO P-Lube Oil | E12: LO P-Schmieröl | F12: 100 | G12: 17 | H12: Messstellen_Mon_Prot_Neu_AbFSW_2_4_ECU9
A13: 16 | B13: 2.0100.922 | C13: 2.0100.902 | D13: SS P-Lube Oil | E13: SS P-Schmieröl | F13: 100 | G13: 1 | H13: Messstellen_Mon_Prot_Neu_AbFSW_2_4_ECU9
A14: 19 | B14: 2.0126.931 | C14: 2.0126.911 | D14: HI T-Exhaust A | E14: HI T-Abgas A | F14: 2434 | G14: 15 | H14: Messstellen_Mon_Prot_Neu_AbFSW_2_4_ECU9
A15: 20 | B15: 2.0126.932 | C15: 2.0126.912 | D15: SS T-Exhaust A | E15: SS T-Abgas A | F15: 2434 | G15: 0 | H15: Messstellen_Mon_Prot_Neu_AbFSW_2_4_ECU9
A16: 21 | B16: 2.0127.931 | C16: 2.0127.911 | D16: HI T-Exhaust B | E16: HI T-Abgas B | F16: 2433 | G16: 15 | H16: Messstellen_Mon_Prot_Neu_AbFSW_2_4_ECU9
A17: 22 | B17: 2.0127.932 | C17: 2.0127.912 | D17: SS T-Exhaust B | E17: SS T-Abgas B | F17: 2433 | G17: 0 | H17: Messstellen_Mon_Prot_Neu_AbFSW_2_4_ECU9
A18: 23 | B18: 2.0152.921 | C18: 2.0152.901 | D18: LO Coolant Level | E18: LO Kuehlmittel Niveau | F18: 111 | G18: 17
A19: 24 | B19: 2.0152.912 | C19: 2.0152.902 | D19: SS Coolant Level | E19: SS Kuehlmittel Niveau | F19: - | G19: -
A20: 25 | B20: 2.0154.931 | C20: 2.0154.911 | D20: HI P-Diff-Lube Oil | E20: HI P-Diff-Schmieröl | F20: 99 | G20: 15 | H20: Messstellen_Mon_Prot_Neu_AbFSW_2_4_ECU9
A21: 26 | B21: 2.0154.932 | C21: 2.0154.912 | D21: SS P-Diff-Lube Oil | E21: SS P-Diff-Schmieröl | F21: 99 | G21: 0 | H21: Messstellen_Mon_Prot_Neu_AbFSW_2_4_ECU9
A22: 27 | B22: 2.0151.931 | C22: 2.0151.911 | D22: HI Level Leakage Fuel | E22: HI Niveau Leckkraftstoff | F22: 1239 | G22: 15 | H22: Messstellen_Mon_Prot_Neu_AbFSW_2_4_ECU9
A23: 29 | B23: 1.8004.206 | C23: 1.8000.078 | D23: HI ETC Idle Speed too High | E23: HI ATL Trudeldrehzahl zu hoch | F23: 521432 | G23: 31
A24: 30 | B24: 2.2510.932 | C24: 2.2510.912 | D24: SS Engine Overspeed | E24: SS Motor Ueberdrehzahl | F24: 190 | G24: 0 | H24: Messstellen_Mon_Prot_Neu_AbFSW_2_4_ECU9
A25: 31 | B25: 2.3011.931 | C25: 2.3012.911 | D25: HI ETC1 Overspeed | E25: HI ATL1 Überdrehzahl | F25: 103 | G25: 15 | H25: Messstellen_Mon_Prot_Neu_AbFSW_2_4_ECU9
A26: 32 | B26: 2.3012.932 | C26: 2.3012.912 | D26: SS ETC1 Overspeed | E26: SS ATL1 Ueberdrehzahl | F26: 103 | G26: 16 | H26: Messstellen_Mon_Prot_Neu_AbFSW_2_4_ECU9
A27: 33 | B27: 2.0114.931 | C27: 2.0114.911 | D27: HI P-Diff-Fuel | E27: HI P-Diff-Kraftstoff | F27: 95 | G27: 15 | H27: Messstellen_Mon_Prot_Neu_AbFSW_2_4_ECU9
A28: 34 | B28: 2.0114.932 | C28: 2.0114.912 | D28: SS P-Diff-Fuel | E28: SS P-Diff-Kraftstoff | F28: 95 | G28: 0 | H28: Messstellen_Mon_Prot_Neu_AbFSW_2_4_ECU9
A29: 36 | B29: 2.3013.931 | C29: 2.3013.911 | D29: HI ETC2 Overspeed | E29: HI ATL2 Überdrehzahl | F29: 1169 | G29: 15 | H29: Messstellen_Mon_Prot_Neu_AbFSW_2_4_ECU9
A30: 37 | B30: 2.3013.912 | C30: 2.3013.932 | D30: SS ETC2 Overspeed | E30: SS ATL2 Ueberdrehzahl | F30: 1169 | G30: 16 | H30: Messstellen_Mon_Prot_Neu_AbFSW_2_4_ECU9
A31: 38 | B31: 1.8004.205 | C31: 1.8000.080 | D31: AL ETC Speed Deviation | E31: AL ATL Gleichlaufabweichung | F31: 521433 | G31: 31
A32: 39 | B32: 1.8004.204 | C32: 1.8000.079 | D32: AL ETC2 CutIn Failure | E32: AL ATL2 Zuschaltfehler | F32: 521091 | G32: 31
A33: 44 | B33: 2.0153.921 | C33: 2.0153.901 | D33: LO Coolant Level Intercooler | E33: LO Kühlmittelniveau Intercool | F33: 3668 | G33: 17 | H33: Messstellen_Mon_Prot_Neu_AbFSW_2_4_ECU9
A34: 46 | B34: 2.0157.921 | C34: 2.0157.901 | D34: LO Level Lube Oil | E34: LO Niv. Schmieröl | F34: 98 | G34: 15
A35: 51 | B35: 2.0125.931 | C35: 2.0125.911 | D35: HI T-Lube Oil | E35: HI T-Schmieroel | F35: 175 | G35: 15 | H35: Messstellen_Mon_Prot_Neu_AbFSW_2_4_ECU9
A36: 52 | B36: 2.0125.932 | C36: 2.0125.912 | D36: SS T-Lube Oil | E36: SS T-Schmieroel | F36: 175 | G36: 0 | H36: Messstellen_Mon_Prot_Neu_AbFSW_2_4_ECU9
A37: 53 | B37: 2.0123.931 | C37: 2.0123.911 | D37: HI T-Intake Air | E37: HI T-Ansaugluft | F37: 172 | G37: 15 | H37: Messstellen_Mon_Prot_Neu_AbFSW_2_4_ECU9 | I37: a. SPN 105
A38: 54 | B38: 2.0123.932 | C38: 2.0123.912 | D38: HIHI T-Intake Air | E38: HIHI T-Ansaugluft | F38: 172 | G38: 0 | H38: Messstellen_Mon_Prot_Neu_AbFSW_2_4_ECU9 | I38: a. SPN 105
A39: 57 | B39: 2.0101.921 | C39: 2.0101.901 | D39: LO P-Coolant | E39: LO P-Kühlmittel | F39: 109 | G39: 17 | H39: Messstellen_Mon_Prot_Neu_AbFSW_2_4_ECU9
A40: 58 | B40: 2.0101.922 | C40: 2.0101.902 | D40: SS P-Coolant | E40: SS P-Kühlmittel | F40: 109 | G40: 1 | H40: Messstellen_Mon_Prot_Neu_AbFSW_2_4_ECU9
...

Sheet MMS Alarms - Descriptions
A1: MMS Fehlercodeliste / Alarmliste - Beschreibungen || ECS Error Code List - Descriptions
A2: Diese Liste enthält alle Alarme, die in einer jeden Variante eines MotorManagementSystems (MMS) auftreten können. Dies beinhaltet die Steuergeräte ECU7, ECU8, ECU9 Diesel, ECU9 Gas, EXU_ESD, EXU_EMU9, EXU_CPM, SXU. Jede Gerät für sich mit ihrer Software kann nur einen Teil dieser Alarme erzeugen.
A3: This list contains all error codes that may occur in any system variant of any EngineControlSystem (ECS). This includes the ECS devices ECU7, ECU8, ECU9 Diesel, ECU9 Gas, EXU_ESD, EXU_EMU9, EXU_CPM, SXU. Any such device and software may only set a subset of these error codes.
B4: Stand : See Title page
A5: Alarm Nr. / Error Code | B5: Beschreibung / Descriptions
A6: 3 | B6: Fuel temperature too high (limit 1).
A7: 4 | B7: Fuel temperature too high (limit 2).
A8: 5 | B8: Charge air temperature too high (limit 1) ==> Check InterCooler
A9: 6 | B9: Charge air temperature too high (limit 2) ==> Check InterCooler
A10: 9 | B10: Coolant temperature of InterCooler too high (limit 1).
A11: 10 | B11: Coolant temperature of InterCooler too high (limit 2).
A12: 15 | B12: Pressure of lube oil too low (limit 1).
A13: 16 | B13: Pressure of lube oil too low (limit 2).
A14: 19 | B14: Exhaust gas temperature (A-side) too high (limit 1).
A15: 20 | B15: Exhaust gas temperature (A-side) too high (limit 2).
A16: 21 | B16: Exhaust gas temperature (B-side) too high (limit 1).
A17: 22 | B17: Exhaust gas temperature (B-side) too high (limit 2).
... A1911: 2103 | B1911: -
A1912: 2104
A1913: 2105 | B1913: H2 percentage too high limit 1
A1914: 2106 | B1914: H2 percentage too high limit 2
A1915: 2107 | B1915: H2 percentage too high limit 3
A1916: 2108 | B1916: H2 sensor defect
A1917: 2109 | B1917: H2 percentage gradient exceed limit 1
A1918: 2110 | B1918: H2 percentage gradient exceed limit 2
A1919: 2111 | B1919: Connector X2 disconnected of powered ECU
A1920: 2112 | B1920: Connector X3 disconnected of powered ECU
A1921: 2113 | B1921: Connector X43 disconnected of powered DCM with ID2
A1922: 2114 | B1922: Connector X43 disconnected of powered DCM with ID3
A1923: 2115 | B1923: Connector X43 disconnected of powered DCM with ID4
A1924: 2116 | B1924: Connector X43 disconnected of powered DCM with ID5
... A2156: 6038 | B2156: open load or short ciurcuit at input for feedback of gas governor valve
A2157: 6039 | B2157: short circuit or open load at transisitor output for turn release valve
A2158: 6040 | B2158: short circuit or open load at transisitor output for turn valve
A2159: 6042 | B2159: Alarm X32 connector is unplugged.
A2160: 6043 | B2160: AL Sensor defect Pressure Raw Water Pump Outlet
A2161: 6044 | B2161: AL Raw water pressure after pump is lower than first lower limit LO1
A2162: 6045 | B2162: AL Sensor defect Pressure Raw Water after Pump
A2163: 6046 | B2163: AL Raw water pressure after pump is lower than first lower limit LO1
A2164: 6047 | B2164: AL Raw water pressure pump oultet is lower than first lower limit LO2
...

Sheet Suche - Search
A1: Suche nach Alarmen || Search for Error Codes
A2: Schreibe die gesuchten Alarmnummern in Spalte Alarm Nr. => Die zu dem Alarm gehörenden Informationen werden rechts daneben angezeigt. Wird eine Alarmnummer nicht gefunden, so ändert sich die Anzeige nicht. Fill in the error codes you are looking for into column Error Code => Error code information is displayed in the cells on the right. If the error code could not be found then the display does not change.
A3: Alarm Nr. / Error Code | B3: Parameter z.k.p.-Nr. | C3: PV z.k.p.-Nr. | D3: Name (English) | E3: Name (Deutsch) | F3: SAE J1939 SPN | G3: count | H3: Entries below means, the Alarm in A5 has additional information.
B4: Description | F4: FMI | G4: =COUNTIF('MMS Alarms - Names'!$A$6:$A$3644,$A$5)+5-ROW('MMS Alarms - Names'!F5) -> 0 | H4: Alarm Nr. / Error Code | I4: Additional Information | J4: SAE J1939 SPN | K4: FMI
B5: =VLOOKUP($A5,'MMS Alarms - Names'!$A$6:$B$4233,2,FALSE) -> #N/A | C5: =VLOOKUP($A5,'MMS Alarms - Names'!$A$6:$C$4233,3,FALSE) -> #N/A | D5: =VLOOKUP($A5,'MMS Alarms - Names'!$A$6:$D$4233,4,FALSE) -> #N/A | E5: =VLOOKUP($A5,'MMS Alarms - Names'!$A$6:$E$4233,5,FALSE) -> #N/A | F5: =VLOOKUP(A5,'MMS Alarms - Names'!$A$6:$G$4233,6,FALSE) -> #N/A | H5: {=IF($G$4>1,IFERROR(INDEX('MMS Alarms - Names'!$A$6:$A$3873,LARGE(('MMS Alarms - Names'!$A$6:$A$3873=$A$5)*(ROW('MMS Alarms - Names'!$A$6:$A$3873)-5),COUNTIF('MMS Alarms - Names'!$A$6:$A$3873,$A$5)+5-ROW('MMS Alarms - Names'!F5))),""),"")} | I5: {=IF($G$4>1,IFERROR(INDEX('MMS Alarms - Names'!$I$6:$I$3873,LARGE(('MMS Alarms - Names'!$A$6:$A$3873=$A$5)*(ROW('MMS Alarms - Names'!$A$6:$A$3873)-5),COUNTIF('MMS Alarms - Names'!$A$6:$A$3873,$A$5)+5-ROW('MMS Alarms - Names'!G5))),""),"")} | J5: {=IF($G$4>1,IFERROR(INDEX('MMS Alarms - Names'!$F$6:$F$3873,LARGE(('MMS Alarms - Names'!$A$6:$A$3873=$A$5)*(ROW('MMS Alarms - Names'!$A$6:$A$3873)-5),COUNTIF('MMS Alarms - Names'!$A$6:$A$3873,$A$5)+5-ROW('MMS Alarms - Names'!G5))),""),"")} | K5: {=IF($G$4>1,IFERROR(INDEX('MMS Alarms - Names'!$G$6:$G$3873,LARGE(('MMS Alarms - Names'!$A$6:$A$3873=$A$5)*(ROW('MMS Alarms - Names'!$A$6:$A$3873)-5),COUNTIF('MMS Alarms - Names'!$A$6:$A$3873,$A$5)+5-ROW('MMS Alarms - Names'!H5))),""),"")}
B6: =VLOOKUP($A5,'MMS Alarms - Descriptions'!$A$6:$B$3249,2,FALSE) -> #N/A | F6: =VLOOKUP(A5,'MMS Alarms - Names'!$A$6:$G$4233,7,FALSE) -> #N/A | H6: {=IF($G$4>1,IFERROR(INDEX('MMS Alarms - Names'!$A$6:$A$3644,LARGE(('MMS Alarms - Names'!$A$6:$A$3644=$A$5)*(ROW('MMS Alarms - Names'!$A$6:$A$3644)-5),COUNTIF('MMS Alarms - Names'!$A$6:$A$3644,$A$5)+5-ROW('MMS Alarms - Names'!F6))),""),"")} | I6: {=IF($G$4>1,IFERROR(INDEX('MMS Alarms - Names'!$I$6:$I$3644,LARGE(('MMS Alarms - Names'!$A$6:$A$3644=$A$5)*(ROW('MMS Alarms - Names'!$A$6:$A$3644)-5),COUNTIF('MMS Alarms - Names'!$A$6:$A$3644,$A$5)+5-ROW('MMS Alarms - Names'!G6))),""),"")} | J6: {=IF($G$4>1,IFERROR(INDEX('MMS Alarms - Names'!$F$6:$F$3644,LARGE(('MMS Alarms - Names'!$A$6:$A$3644=$A$5)*(ROW('MMS Alarms - Names'!$A$6:$A$3644)-5),COUNTIF('MMS Alarms - Names'!$A$6:$A$3644,$A$5)+5-ROW('MMS Alarms - Names'!G6))),""),"")} | K6: {=IF($G$4>1,IFERROR(INDEX('MMS Alarms - Names'!$G$6:$G$3644,LARGE(('MMS Alarms - Names'!$A$6:$A$3644=$A$5)*(ROW('MMS Alarms - Names'!$A$6:$A$3644)-5),COUNTIF('MMS Alarms - Names'!$A$6:$A$3644,$A$5)+5-ROW('MMS Alarms - Names'!H6))),""),"")}
B7: =VLOOKUP($A7,'MMS Alarms - Names'!$A$6:$B$4233,2,FALSE) -> #N/A | C7: =VLOOKUP($A7,'MMS Alarms - Names'!$A$6:$C$4233,3,FALSE) -> #N/A | D7: =VLOOKUP($A7,'MMS Alarms - Names'!$A$6:$D$4233,4,FALSE) -> #N/A | E7: =VLOOKUP($A7,'MMS Alarms - Names'!$A$6:$E$4233,5,FALSE) -> #N/A | F7: =VLOOKUP(A7,'MMS Alarms - Names'!$A$6:$G$4233,6,FALSE) -> #N/A | H7: {=IF($G$4>1,IFERROR(INDEX('MMS Alarms - Names'!$A$6:$A$3644,LARGE(('MMS Alarms - Names'!$A$6:$A$3644=$A$5)*(ROW('MMS Alarms - Names'!$A$6:$A$3644)-5),COUNTIF('MMS Alarms - Names'!$A$6:$A$3644,$A$5)+5-ROW('MMS Alarms - Names'!F7))),""),"")} | I7: {=IF($G$4>1,IFERROR(INDEX('MMS Alarms - Names'!$I$6:$I$3644,LARGE(('MMS Alarms - Names'!$A$6:$A$3644=$A$5)*(ROW('MMS Alarms - Names'!$A$6:$A$3644)-5),COUNTIF('MMS Alarms - Names'!$A$6:$A$3644,$A$5)+5-ROW('MMS Alarms - Names'!G7))),""),"")} | J7: {=IF($G$4>1,IFERROR(INDEX('MMS Alarms - Names'!$F$6:$F$3644,LARGE(('MMS Alarms - Names'!$A$6:$A$3644=$A$5)*(ROW('MMS Alarms - Names'!$A$6:$A$3644)-5),COUNTIF('MMS Alarms - Names'!$A$6:$A$3644,$A$5)+5-ROW('MMS Alarms - Names'!G7))),""),"")} | K7: {=IF($G$4>1,IFERROR(INDEX('MMS Alarms - Names'!$G$6:$G$3644,LARGE(('MMS Alarms - Names'!$A$6:$A$3644=$A$5)*(ROW('MMS Alarms - Names'!$A$6:$A$3644)-5),COUNTIF('MMS Alarms - Names'!$A$6:$A$3644,$A$5)+5-ROW('MMS Alarms - Names'!H7))),""),"")}
B8: =VLOOKUP($A7,'MMS Alarms - Descriptions'!$A$6:$B$3249,2,FALSE) -> #N/A | F8: =VLOOKUP(A7,'MMS Alarms - Names'!$A$6:$G$4233,7,FALSE) -> #N/A | H8: {=IF($G$4>1,IFERROR(INDEX('MMS Alarms - Names'!$A$6:$A$3644,LARGE(('MMS Alarms - Names'!$A$6:$A$3644=$A$5)*(ROW('MMS Alarms - Names'!$A$6:$A$3644)-5),COUNTIF('MMS Alarms - Names'!$A$6:$A$3644,$A$5)+5-ROW('MMS Alarms - Names'!F8))),""),"")} | I8: {=IF($G$4>1,IFERROR(INDEX('MMS Alarms - Names'!$I$6:$I$3644,LARGE(('MMS Alarms - Names'!$A$6:$A$3644=$A$5)*(ROW('MMS Alarms - Names'!$A$6:$A$3644)-5),COUNTIF('MMS Alarms - Names'!$A$6:$A$3644,$A$5)+5-ROW('MMS Alarms - Names'!G8))),""),"")} | J8: {=IF($G$4>1,IFERROR(INDEX('MMS Alarms - Names'!$F$6:$F$3644,LARGE(('MMS Alarms - Names'!$A$6:$A$3644=$A$5)*(ROW('MMS Alarms - Names'!$A$6:$A$3644)-5),COUNTIF('MMS Alarms - Names'!$A$6:$A$3644,$A$5)+5-ROW('MMS Alarms - Names'!G8))),""),"")} | K8: {=IF($G$4>1,IFERROR(INDEX('MMS Alarms - Names'!$G$6:$G$3644,LARGE(('MMS Alarms - Names'!$A$6:$A$3644=$A$5)*(ROW('MMS Alarms - Names'!$A$6:$A$3644)-5),COUNTIF('MMS Alarms - Names'!$A$6:$A$3644,$A$5)+5-ROW('MMS Alarms - Names'!H8))),""),"")}
B9: =VLOOKUP($A9,'MMS Alarms - Names'!$A$6:$B$4233,2,FALSE) -> #N/A | C9: =VLOOKUP($A9,'MMS Alarms - Names'!$A$6:$C$4233,3,FALSE) -> #N/A | D9: =VLOOKUP($A9,'MMS Alarms - Names'!$A$6:$D$4233,4,FALSE) -> #N/A | E9: =VLOOKUP($A9,'MMS Alarms - Names'!$A$6:$E$4233,5,FALSE) -> #N/A | F9: =VLOOKUP(A9,'MMS Alarms - Names'!$A$6:$G$4233,6,FALSE) -> #N/A | H9: {=IF($G$4>1,IFERROR(INDEX('MMS Alarms - Names'!$A$6:$A$3644,LARGE(('MMS Alarms - Names'!$A$6:$A$3644=$A$5)*(ROW('MMS Alarms - Names'!$A$6:$A$3644)-5),COUNTIF('MMS Alarms - Names'!$A$6:$A$3644,$A$5)+5-ROW('MMS Alarms - Names'!F9))),""),"")} | I9: {=IF($G$4>1,IFERROR(INDEX('MMS Alarms - Names'!$I$6:$I$3644,LARGE(('MMS Alarms - Names'!$A$6:$A$3644=$A$5)*(ROW('MMS Alarms - Names'!$A$6:$A$3644)-5),COUNTIF('MMS Alarms - Names'!$A$6:$A$3644,$A$5)+5-ROW('MMS Alarms - Names'!G9))),""),"")} | J9: {=IF($G$4>1,IFERROR(INDEX('MMS Alarms - Names'!$F$6:$F$3644,LARGE(('MMS Alarms - Names'!$A$6:$A$3644=$A$5)*(ROW('MMS Alarms - Names'!$A$6:$A$3644)-5),COUNTIF('MMS Alarms - Names'!$A$6:$A$3644,$A$5)+5-ROW('MMS Alarms - Names'!G9))),""),"")} | K9: {=IF($G$4>1,IFERROR(INDEX('MMS Alarms - Names'!$G$6:$G$3644,LARGE(('MMS Alarms - Names'!$A$6:$A$3644=$A$5)*(ROW('MMS Alarms - Names'!$A$6:$A$3644)-5),COUNTIF('MMS Alarms - Names'!$A$6:$A$3644,$A$5)+5-ROW('MMS Alarms - Names'!H9))),""),"")}
B10: =VLOOKUP($A9,'MMS Alarms - Descriptions'!$A$6:$B$3249,2,FALSE) -> #N/A | F10: =VLOOKUP(A9,'MMS Alarms - Names'!$A$6:$G$4233,7,FALSE) -> #N/A | H10: {=IF($G$4>1,IFERROR(INDEX('MMS Alarms - Names'!$A$6:$A$3644,LARGE(('MMS Alarms - Names'!$A$6:$A$3644=$A$5)*(ROW('MMS Alarms - Names'!$A$6:$A$3644)-5),COUNTIF('MMS Alarms - Names'!$A$6:$A$3644,$A$5)+5-ROW('MMS Alarms - Names'!F10))),""),"")} | I10: {=IF($G$4>1,IFERROR(INDEX('MMS Alarms - Names'!$I$6:$I$3644,LARGE(('MMS Alarms - Names'!$A$6:$A$3644=$A$5)*(ROW('MMS Alarms - Names'!$A$6:$A$3644)-5),COUNTIF('MMS Alarms - Names'!$A$6:$A$3644,$A$5)+5-ROW('MMS Alarms - Names'!G10))),""),"")} | J10: {=IF($G$4>1,IFERROR(INDEX('MMS Alarms - Names'!$F$6:$F$3644,LARGE(('MMS Alarms - Names'!$A$6:$A$3644=$A$5)*(ROW('MMS Alarms - Names'!$A$6:$A$3644)-5),COUNTIF('MMS Alarms - Names'!$A$6:$A$3644,$A$5)+5-ROW('MMS Alarms - Names'!G10))),""),"")} | K10: {=IF($G$4>1,IFERROR(INDEX('MMS Alarms - Names'!$G$6:$G$3644,LARGE(('MMS Alarms - Names'!$A$6:$A$3644=$A$5)*(ROW('MMS Alarms - Names'!$A$6:$A$3644)-5),COUNTIF('MMS Alarms - Names'!$A$6:$A$3644,$A$5)+5-ROW('MMS Alarms - Names'!H10))),""),"")}
B11: =VLOOKUP($A11,'MMS Alarms - Names'!$A$6:$B$4233,2,FALSE) -> #N/A | C11: =VLOOKUP($A11,'MMS Alarms - Names'!$A$6:$C$4233,3,FALSE) -> #N/A | D11: =VLOOKUP($A11,'MMS Alarms - Names'!$A$6:$D$4233,4,FALSE) -> #N/A | E11: =VLOOKUP($A11,'MMS Alarms - Names'!$A$6:$E$4233,5,FALSE) -> #N/A | F11: =VLOOKUP(A11,'MMS Alarms - Names'!$A$6:$G$4233,6,FALSE) -> #N/A | H11: {=IF($G$4>1,IFERROR(INDEX('MMS Alarms - Names'!$A$6:$A$3644,LARGE(('MMS Alarms - Names'!$A$6:$A$3644=$A$5)*(ROW('MMS Alarms - Names'!$A$6:$A$3644)-5),COUNTIF('MMS Alarms - Names'!$A$6:$A$3644,$A$5)+5-ROW('MMS Alarms - Names'!F11))),""),"")} | I11: {=IF($G$4>1,IFERROR(INDEX('MMS Alarms - Names'!$I$6:$I$3644,LARGE(('MMS Alarms - Names'!$A$6:$A$3644=$A$5)*(ROW('MMS Alarms - Names'!$A$6:$A$3644)-5),COUNTIF('MMS Alarms - Names'!$A$6:$A$3644,$A$5)+5-ROW('MMS Alarms - Names'!G11))),""),"")} | J11: {=IF($G$4>1,IFERROR(INDEX('MMS Alarms - Names'!$F$6:$F$3644,LARGE(('MMS Alarms - Names'!$A$6:$A$3644=$A$5)*(ROW('MMS Alarms - Names'!$A$6:$A$3644)-5),COUNTIF('MMS Alarms - Names'!$A$6:$A$3644,$A$5)+5-ROW('MMS Alarms - Names'!G11))),""),"")} | K11: {=IF($G$4>1,IFERROR(INDEX('MMS Alarms - Names'!$G$6:$G$3644,LARGE(('MMS Alarms - Names'!$A$6:$A$3644=$A$5)*(ROW('MMS Alarms - Names'!$A$6:$A$3644)-5),COUNTIF('MMS Alarms - Names'!$A$6:$A$3644,$A$5)+5-ROW('MMS Alarms - Names'!H11))),""),"")}
B12: =VLOOKUP($A11,'MMS Alarms - Descriptions'!$A$6:$B$3249,2,FALSE) -> #N/A | F12: =VLOOKUP(A11,'MMS Alarms - Names'!$A$6:$G$4233,7,FALSE) -> #N/A | H12: {=IF($G$4>1,IFERROR(INDEX('MMS Alarms - Names'!$A$6:$A$3644,LARGE(('MMS Alarms - Names'!$A$6:$A$3644=$A$5)*(ROW('MMS Alarms - Names'!$A$6:$A$3644)-5),COUNTIF('MMS Alarms - Names'!$A$6:$A$3644,$A$5)+5-ROW('MMS Alarms - Names'!F12))),""),"")} | I12: {=IF($G$4>1,IFERROR(INDEX('MMS Alarms - Names'!$I$6:$I$3644,LARGE(('MMS Alarms - Names'!$A$6:$A$3644=$A$5)*(ROW('MMS Alarms - Names'!$A$6:$A$3644)-5),COUNTIF('MMS Alarms - Names'!$A$6:$A$3644,$A$5)+5-ROW('MMS Alarms - Names'!G12))),""),"")} | J12: {=IF($G$4>1,IFERROR(INDEX('MMS Alarms - Names'!$F$6:$F$3644,LARGE(('MMS Alarms - Names'!$A$6:$A$3644=$A$5)*(ROW('MMS Alarms - Names'!$A$6:$A$3644)-5),COUNTIF('MMS Alarms - Names'!$A$6:$A$3644,$A$5)+5-ROW('MMS Alarms - Names'!G12))),""),"")} | K12: {=IF($G$4>1,IFERROR(INDEX('MMS Alarms - Names'!$G$6:$G$3644,LARGE(('MMS Alarms - Names'!$A$6:$A$3644=$A$5)*(ROW('MMS Alarms - Names'!$A$6:$A$3644)-5),COUNTIF('MMS Alarms - Names'!$A$6:$A$3644,$A$5)+5-ROW('MMS Alarms - Names'!H12))),""),"")}
B13: =VLOOKUP($A13,'MMS Alarms - Names'!$A$6:$B$4233,2,FALSE) -> #N/A | C13: =VLOOKUP($A13,'MMS Alarms - Names'!$A$6:$C$4233,3,FALSE) -> #N/A | D13: =VLOOKUP($A13,'MMS Alarms - Names'!$A$6:$D$4233,4,FALSE) -> #N/A | E13: =VLOOKUP($A13,'MMS Alarms - Names'!$A$6:$E$4233,5,FALSE) -> #N/A | F13: =VLOOKUP(A13,'MMS Alarms - Names'!$A$6:$G$4233,6,FALSE) -> #N/A | H13: {=IF($G$4>1,IFERROR(INDEX('MMS Alarms - Names'!$A$6:$A$3644,LARGE(('MMS Alarms - Names'!$A$6:$A$3644=$A$5)*(ROW('MMS Alarms - Names'!$A$6:$A$3644)-5),COUNTIF('MMS Alarms - Names'!$A$6:$A$3644,$A$5)+5-ROW('MMS Alarms - Names'!F13))),""),"")} | I13: {=IF($G$4>1,IFERROR(INDEX('MMS Alarms - Names'!$I$6:$I$3644,LARGE(('MMS Alarms - Names'!$A$6:$A$3644=$A$5)*(ROW('MMS Alarms - Names'!$A$6:$A$3644)-5),COUNTIF('MMS Alarms - Names'!$A$6:$A$3644,$A$5)+5-ROW('MMS Alarms - Names'!G13))),""),"")} | J13: {=IF($G$4>1,IFERROR(INDEX('MMS Alarms - Names'!$F$6:$F$3644,LARGE(('MMS Alarms - Names'!$A$6:$A$3644=$A$5)*(ROW('MMS Alarms - Names'!$A$6:$A$3644)-5),COUNTIF('MMS Alarms - Names'!$A$6:$A$3644,$A$5)+5-ROW('MMS Alarms - Names'!G13))),""),"")} | K13: {=IF($G$4>1,IFERROR(INDEX('MMS Alarms - Names'!$G$6:$G$3644,LARGE(('MMS Alarms - Names'!$A$6:$A$3644=$A$5)*(ROW('MMS Alarms - Names'!$A$6:$A$3644)-5),COUNTIF('MMS Alarms - Names'!$A$6:$A$3644,$A$5)+5-ROW('MMS Alarms - Names'!H13))),""),"")}
B14: =VLOOKUP($A13,'MMS Alarms - Descriptions'!$A$6:$B$3249,2,FALSE) -> #N/A | F14: =VLOOKUP(A13,'MMS Alarms - Names'!$A$6:$G$4233,7,FALSE) -> #N/A | H14: {=IF($G$4>1,IFERROR(INDEX('MMS Alarms - Names'!$A$6:$A$3644,LARGE(('MMS Alarms - Names'!$A$6:$A$3644=$A$5)*(ROW('MMS Alarms - Names'!$A$6:$A$3644)-5),COUNTIF('MMS Alarms - Names'!$A$6:$A$3644,$A$5)+5-ROW('MMS Alarms - Names'!F14))),""),"")} | I14: {=IF($G$4>1,IFERROR(INDEX('MMS Alarms - Names'!$I$6:$I$3644,LARGE(('MMS Alarms - Names'!$A$6:$A$3644=$A$5)*(ROW('MMS Alarms - Names'!$A$6:$A$3644)-5),COUNTIF('MMS Alarms - Names'!$A$6:$A$3644,$A$5)+5-ROW('MMS Alarms - Names'!G14))),""),"")} | J14: {=IF($G$4>1,IFERROR(INDEX('MMS Alarms - Names'!$F$6:$F$3644,LARGE(('MMS Alarms - Names'!$A$6:$A$3644=$A$5)*(ROW('MMS Alarms - Names'!$A$6:$A$3644)-5),COUNTIF('MMS Alarms - Names'!$A$6:$A$3644,$A$5)+5-ROW('MMS Alarms - Names'!G14))),""),"")} | K14: {=IF($G$4>1,IFERROR(INDEX('MMS Alarms - Names'!$G$6:$G$3644,LARGE(('MMS Alarms - Names'!$A$6:$A$3644=$A$5)*(ROW('MMS Alarms - Names'!$A$6:$A$3644)-5),COUNTIF('MMS Alarms - Names'!$A$6:$A$3644,$A$5)+5-ROW('MMS Alarms - Names'!H14))),""),"")}
B15: =VLOOKUP($A15,'MMS Alarms - Names'!$A$6:$B$4233,2,FALSE) -> #N/A | C15: =VLOOKUP($A15,'MMS Alarms - Names'!$A$6:$C$4233,3,FALSE) -> #N/A | D15: =VLOOKUP($A15,'MMS Alarms - Names'!$A$6:$D$4233,4,FALSE) -> #N/A | E15: =VLOOKUP($A15,'MMS Alarms - Names'!$A$6:$E$4233,5,FALSE) -> #N/A | F15: =VLOOKUP(A15,'MMS Alarms - Names'!$A$6:$G$4233,6,FALSE) -> #N/A | H15: {=IF($G$4>1,IFERROR(INDEX('MMS Alarms - Names'!$A$6:$A$3644,LARGE(('MMS Alarms - Names'!$A$6:$A$3644=$A$5)*(ROW('MMS Alarms - Names'!$A$6:$A$3644)-5),COUNTIF('MMS Alarms - Names'!$A$6:$A$3644,$A$5)+5-ROW('MMS Alarms - Names'!F15))),""),"")} | I15: {=IF($G$4>1,IFERROR(INDEX('MMS Alarms - Names'!$I$6:$I$3644,LARGE(('MMS Alarms - Names'!$A$6:$A$3644=$A$5)*(ROW('MMS Alarms - Names'!$A$6:$A$3644)-5),COUNTIF('MMS Alarms - Names'!$A$6:$A$3644,$A$5)+5-ROW('MMS Alarms - Names'!G15))),""),"")} | J15: {=IF($G$4>1,IFERROR(INDEX('MMS Alarms - Names'!$F$6:$F$3644,LARGE(('MMS Alarms - Names'!$A$6:$A$3644=$A$5)*(ROW('MMS Alarms - Names'!$A$6:$A$3644)-5),COUNTIF('MMS Alarms - Names'!$A$6:$A$3644,$A$5)+5-ROW('MMS Alarms - Names'!G15))),""),"")} | K15: {=IF($G$4>1,IFERROR(INDEX('MMS Alarms - Names'!$G$6:$G$3644,LARGE(('MMS Alarms - Names'!$A$6:$A$3644=$A$5)*(ROW('MMS Alarms - Names'!$A$6:$A$3644)-5),COUNTIF('MMS Alarms - Names'!$A$6:$A$3644,$A$5)+5-ROW('MMS Alarms - Names'!H15))),""),"")}
B16: =VLOOKUP($A15,'MMS Alarms - Descriptions'!$A$6:$B$3249,2,FALSE) -> #N/A | F16: =VLOOKUP(A15,'MMS Alarms - Names'!$A$6:$G$4233,7,FALSE) -> #N/A | H16: {=IF($G$4>1,IFERROR(INDEX('MMS Alarms - Names'!$A$6:$A$3644,LARGE(('MMS Alarms - Names'!$A$6:$A$3644=$A$5)*(ROW('MMS Alarms - Names'!$A$6:$A$3644)-5),COUNTIF('MMS Alarms - Names'!$A$6:$A$3644,$A$5)+5-ROW('MMS Alarms - Names'!F16))),""),"")} | I16: {=IF($G$4>1,IFERROR(INDEX('MMS Alarms - Names'!$I$6:$I$3644,LARGE(('MMS Alarms - Names'!$A$6:$A$3644=$A$5)*(ROW('MMS Alarms - Names'!$A$6:$A$3644)-5),COUNTIF('MMS Alarms - Names'!$A$6:$A$3644,$A$5)+5-ROW('MMS Alarms - Names'!G16))),""),"")} | J16: {=IF($G$4>1,IFERROR(INDEX('MMS Alarms - Names'!$F$6:$F$3644,LARGE(('MMS Alarms - Names'!$A$6:$A$3644=$A$5)*(ROW('MMS Alarms - Names'!$A$6:$A$3644)-5),COUNTIF('MMS Alarms - Names'!$A$6:$A$3644,$A$5)+5-ROW('MMS Alarms - Names'!G16))),""),"")} | K16: {=IF($G$4>1,IFERROR(INDEX('MMS Alarms - Names'!$G$6:$G$3644,LARGE(('MMS Alarms - Names'!$A$6:$A$3644=$A$5)*(ROW('MMS Alarms - Names'!$A$6:$A$3644)-5),COUNTIF('MMS Alarms - Names'!$A$6:$A$3644,$A$5)+5-ROW('MMS Alarms - Names'!H16))),""),"")}
B17: =VLOOKUP($A17,'MMS Alarms - Names'!$A$6:$B$4233,2,FALSE) -> #N/A | C17: =VLOOKUP($A17,'MMS Alarms - Names'!$A$6:$C$4233,3,FALSE) -> #N/A | D17: =VLOOKUP($A17,'MMS Alarms - Names'!$A$6:$D$4233,4,FALSE) -> #N/A | E17: =VLOOKUP($A17,'MMS Alarms - Names'!$A$6:$E$4233,5,FALSE) -> #N/A | F17: =VLOOKUP(A17,'MMS Alarms - Names'!$A$6:$G$4233,6,FALSE) -> #N/A | H17: {=IF($G$4>1,IFERROR(INDEX('MMS Alarms - Names'!$A$6:$A$3644,LARGE(('MMS Alarms - Names'!$A$6:$A$3644=$A$5)*(ROW('MMS Alarms - Names'!$A$6:$A$3644)-5),COUNTIF('MMS Alarms - Names'!$A$6:$A$3644,$A$5)+5-ROW('MMS Alarms - Names'!F17))),""),"")} | I17: {=IF($G$4>1,IFERROR(INDEX('MMS Alarms - Names'!$I$6:$I$3644,LARGE(('MMS Alarms - Names'!$A$6:$A$3644=$A$5)*(ROW('MMS Alarms - Names'!$A$6:$A$3644)-5),COUNTIF('MMS Alarms - Names'!$A$6:$A$3644,$A$5)+5-ROW('MMS Alarms - Names'!G17))),""),"")} | J17: {=IF($G$4>1,IFERROR(INDEX('MMS Alarms - Names'!$F$6:$F$3644,LARGE(('MMS Alarms - Names'!$A$6:$A$3644=$A$5)*(ROW('MMS Alarms - Names'!$A$6:$A$3644)-5),COUNTIF('MMS Alarms - Names'!$A$6:$A$3644,$A$5)+5-ROW('MMS Alarms - Names'!G17))),""),"")} | K17: {=IF($G$4>1,IFERROR(INDEX('MMS Alarms - Names'!$G$6:$G$3644,LARGE(('MMS Alarms - Names'!$A$6:$A$3644=$A$5)*(ROW('MMS Alarms - Names'!$A$6:$A$3644)-5),COUNTIF('MMS Alarms - Names'!$A$6:$A$3644,$A$5)+5-ROW('MMS Alarms - Names'!H17))),""),"")}
B18: =VLOOKUP($A17,'MMS Alarms - Descriptions'!$A$6:$B$3249,2,FALSE) -> #N/A | F18: =VLOOKUP(A17,'MMS Alarms - Names'!$A$6:$G$4233,7,FALSE) -> #N/A | H18: {=IF($G$4>1,IFERROR(INDEX('MMS Alarms - Names'!$A$6:$A$3644,LARGE(('MMS Alarms - Names'!$A$6:$A$3644=$A$5)*(ROW('MMS Alarms - Names'!$A$6:$A$3644)-5),COUNTIF('MMS Alarms - Names'!$A$6:$A$3644,$A$5)+5-ROW('MMS Alarms - Names'!F18))),""),"")} | I18: {=IF($G$4>1,IFERROR(INDEX('MMS Alarms - Names'!$I$6:$I$3644,LARGE(('MMS Alarms - Names'!$A$6:$A$3644=$A$5)*(ROW('MMS Alarms - Names'!$A$6:$A$3644)-5),COUNTIF('MMS Alarms - Names'!$A$6:$A$3644,$A$5)+5-ROW('MMS Alarms - Names'!G18))),""),"")} | J18: {=IF($G$4>1,IFERROR(INDEX('MMS Alarms - Names'!$F$6:$F$3644,LARGE(('MMS Alarms - Names'!$A$6:$A$3644=$A$5)*(ROW('MMS Alarms - Names'!$A$6:$A$3644)-5),COUNTIF('MMS Alarms - Names'!$A$6:$A$3644,$A$5)+5-ROW('MMS Alarms - Names'!G18))),""),"")} | K18: {=IF($G$4>1,IFERROR(INDEX('MMS Alarms - Names'!$G$6:$G$3644,LARGE(('MMS Alarms - Names'!$A$6:$A$3644=$A$5)*(ROW('MMS Alarms - Names'!$A$6:$A$3644)-5),COUNTIF('MMS Alarms - Names'!$A$6:$A$3644,$A$5)+5-ROW('MMS Alarms - Names'!H18))),""),"")}
B19: =VLOOKUP($A19,'MMS Alarms - Names'!$A$6:$B$4233,2,FALSE) -> #N/A | C19: =VLOOKUP($A19,'MMS Alarms - Names'!$A$6:$C$4233,3,FALSE) -> #N/A | D19: =VLOOKUP($A19,'MMS Alarms - Names'!$A$6:$D$4233,4,FALSE) -> #N/A | E19: =VLOOKUP($A19,'MMS Alarms - Names'!$A$6:$E$4233,5,FALSE) -> #N/A | F19: =VLOOKUP(A19,'MMS Alarms - Names'!$A$6:$G$4233,6,FALSE) -> #N/A | H19: {=IF($G$4>1,IFERROR(INDEX('MMS Alarms - Names'!$A$6:$A$3644,LARGE(('MMS Alarms - Names'!$A$6:$A$3644=$A$5)*(ROW('MMS Alarms - Names'!$A$6:$A$3644)-5),COUNTIF('MMS Alarms - Names'!$A$6:$A$3644,$A$5)+5-ROW('MMS Alarms - Names'!F19))),""),"")} | I19: {=IF($G$4>1,IFERROR(INDEX('MMS Alarms - Names'!$I$6:$I$3644,LARGE(('MMS Alarms - Names'!$A$6:$A$3644=$A$5)*(ROW('MMS Alarms - Names'!$A$6:$A$3644)-5),COUNTIF('MMS Alarms - Names'!$A$6:$A$3644,$A$5)+5-ROW('MMS Alarms - Names'!G19))),""),"")} | J19: {=IF($G$4>1,IFERROR(INDEX('MMS Alarms - Names'!$F$6:$F$3644,LARGE(('MMS Alarms - Names'!$A$6:$A$3644=$A$5)*(ROW('MMS Alarms - Names'!$A$6:$A$3644)-5),COUNTIF('MMS Alarms - Names'!$A$6:$A$3644,$A$5)+5-ROW('MMS Alarms - Names'!G19))),""),"")} | K19: {=IF($G$4>1,IFERROR(INDEX('MMS Alarms - Names'!$G$6:$G$3644,LARGE(('MMS Alarms - Names'!$A$6:$A$3644=$A$5)*(ROW('MMS Alarms - Names'!$A$6:$A$3644)-5),COUNTIF('MMS Alarms - Names'!$A$6:$A$3644,$A$5)+5-ROW('MMS Alarms - Names'!H19))),""),"")}
B20: =VLOOKUP($A19,'MMS Alarms - Descriptions'!$A$6:$B$3249,2,FALSE) -> #N/A | F20: =VLOOKUP(A19,'MMS Alarms - Names'!$A$6:$G$4233,7,FALSE) -> #N/A | H20: {=IF($G$4>1,IFERROR(INDEX('MMS Alarms - Names'!$A$6:$A$3644,LARGE(('MMS Alarms - Names'!$A$6:$A$3644=$A$5)*(ROW('MMS Alarms - Names'!$A$6:$A$3644)-5),COUNTIF('MMS Alarms - Names'!$A$6:$A$3644,$A$5)+5-ROW('MMS Alarms - Names'!F20))),""),"")} | I20: {=IF($G$4>1,IFERROR(INDEX('MMS Alarms - Names'!$I$6:$I$3644,LARGE(('MMS Alarms - Names'!$A$6:$A$3644=$A$5)*(ROW('MMS Alarms - Names'!$A$6:$A$3644)-5),COUNTIF('MMS Alarms - Names'!$A$6:$A$3644,$A$5)+5-ROW('MMS Alarms - Names'!G20))),""),"")} | J20: {=IF($G$4>1,IFERROR(INDEX('MMS Alarms - Names'!$F$6:$F$3644,LARGE(('MMS Alarms - Names'!$A$6:$A$3644=$A$5)*(ROW('MMS Alarms - Names'!$A$6:$A$3644)-5),COUNTIF('MMS Alarms - Names'!$A$6:$A$3644,$A$5)+5-ROW('MMS Alarms - Names'!G20))),""),"")} | K20: {=IF($G$4>1,IFERROR(INDEX('MMS Alarms - Names'!$G$6:$G$3644,LARGE(('MMS Alarms - Names'!$A$6:$A$3644=$A$5)*(ROW('MMS Alarms - Names'!$A$6:$A$3644)-5),COUNTIF('MMS Alarms - Names'!$A$6:$A$3644,$A$5)+5-ROW('MMS Alarms - Names'!H20))),""),"")}
B21: =VLOOKUP($A21,'MMS Alarms - Names'!$A$6:$B$4233,2,FALSE) -> #N/A | C21: =VLOOKUP($A21,'MMS Alarms - Names'!$A$6:$C$4233,3,FALSE) -> #N/A | D21: =VLOOKUP($A21,'MMS Alarms - Names'!$A$6:$D$4233,4,FALSE) -> #N/A | E21: =VLOOKUP($A21,'MMS Alarms - Names'!$A$6:$E$4233,5,FALSE) -> #N/A | F21: =VLOOKUP(A21,'MMS Alarms - Names'!$A$6:$G$4233,6,FALSE) -> #N/A | H21: {=IF($G$4>1,IFERROR(INDEX('MMS Alarms - Names'!$A$6:$A$3644,LARGE(('MMS Alarms - Names'!$A$6:$A$3644=$A$5)*(ROW('MMS Alarms - Names'!$A$6:$A$3644)-5),COUNTIF('MMS Alarms - Names'!$A$6:$A$3644,$A$5)+5-ROW('MMS Alarms - Names'!F21))),""),"")} | I21: {=IF($G$4>1,IFERROR(INDEX('MMS Alarms - Names'!$I$6:$I$3644,LARGE(('MMS Alarms - Names'!$A$6:$A$3644=$A$5)*(ROW('MMS Alarms - Names'!$A$6:$A$3644)-5),COUNTIF('MMS Alarms - Names'!$A$6:$A$3644,$A$5)+5-ROW('MMS Alarms - Names'!G21))),""),"")} | J21: {=IF($G$4>1,IFERROR(INDEX('MMS Alarms - Names'!$F$6:$F$3644,LARGE(('MMS Alarms - Names'!$A$6:$A$3644=$A$5)*(ROW('MMS Alarms - Names'!$A$6:$A$3644)-5),COUNTIF('MMS Alarms - Names'!$A$6:$A$3644,$A$5)+5-ROW('MMS Alarms - Names'!G21))),""),"")} | K21: {=IF($G$4>1,IFERROR(INDEX('MMS Alarms - Names'!$G$6:$G$3644,LARGE(('MMS Alarms - Names'!$A$6:$A$3644=$A$5)*(ROW('MMS Alarms - Names'!$A$6:$A$3644)-5),COUNTIF('MMS Alarms - Names'!$A$6:$A$3644,$A$5)+5-ROW('MMS Alarms - Names'!H21))),""),"")}
B22: =VLOOKUP($A21,'MMS Alarms - Descriptions'!$A$6:$B$3249,2,FALSE) -> #N/A | F22: =VLOOKUP(A21,'MMS Alarms - Names'!$A$6:$G$4233,7,FALSE) -> #N/A | H22: {=IF($G$4>1,IFERROR(INDEX('MMS Alarms - Names'!$A$6:$A$3644,LARGE(('MMS Alarms - Names'!$A$6:$A$3644=$A$5)*(ROW('MMS Alarms - Names'!$A$6:$A$3644)-5),COUNTIF('MMS Alarms - Names'!$A$6:$A$3644,$A$5)+5-ROW('MMS Alarms - Names'!F22))),""),"")} | I22: {=IF($G$4>1,IFERROR(INDEX('MMS Alarms - Names'!$I$6:$I$3644,LARGE(('MMS Alarms - Names'!$A$6:$A$3644=$A$5)*(ROW('MMS Alarms - Names'!$A$6:$A$3644)-5),COUNTIF('MMS Alarms - Names'!$A$6:$A$3644,$A$5)+5-ROW('MMS Alarms - Names'!G22))),""),"")} | J22: {=IF($G$4>1,IFERROR(INDEX('MMS Alarms - Names'!$F$6:$F$3644,LARGE(('MMS Alarms - Names'!$A$6:$A$3644=$A$5)*(ROW('MMS Alarms - Names'!$A$6:$A$3644)-5),COUNTIF('MMS Alarms - Names'!$A$6:$A$3644,$A$5)+5-ROW('MMS Alarms - Names'!G22))),""),"")} | K22: {=IF($G$4>1,IFERROR(INDEX('MMS Alarms - Names'!$G$6:$G$3644,LARGE(('MMS Alarms - Names'!$A$6:$A$3644=$A$5)*(ROW('MMS Alarms - Names'!$A$6:$A$3644)-5),COUNTIF('MMS Alarms - Names'!$A$6:$A$3644,$A$5)+5-ROW('MMS Alarms - Names'!H22))),""),"")}
B23: =VLOOKUP($A23,'MMS Alarms - Names'!$A$6:$B$4233,2,FALSE) -> #N/A | C23: =VLOOKUP($A23,'MMS Alarms - Names'!$A$6:$C$4233,3,FALSE) -> #N/A | D23: =VLOOKUP($A23,'MMS Alarms - Names'!$A$6:$D$4233,4,FALSE) -> #N/A | E23: =VLOOKUP($A23,'MMS Alarms - Names'!$A$6:$E$4233,5,FALSE) -> #N/A | F23: =VLOOKUP(A23,'MMS Alarms - Names'!$A$6:$G$4233,6,FALSE) -> #N/A | H23: {=IF($G$4>1,IFERROR(INDEX('MMS Alarms - Names'!$A$6:$A$3644,LARGE(('MMS Alarms - Names'!$A$6:$A$3644=$A$5)*(ROW('MMS Alarms - Names'!$A$6:$A$3644)-5),COUNTIF('MMS Alarms - Names'!$A$6:$A$3644,$A$5)+5-ROW('MMS Alarms - Names'!F23))),""),"")} | I23: {=IF($G$4>1,IFERROR(INDEX('MMS Alarms - Names'!$I$6:$I$3644,LARGE(('MMS Alarms - Names'!$A$6:$A$3644=$A$5)*(ROW('MMS Alarms - Names'!$A$6:$A$3644)-5),COUNTIF('MMS Alarms - Names'!$A$6:$A$3644,$A$5)+5-ROW('MMS Alarms - Names'!G23))),""),"")} | J23: {=IF($G$4>1,IFERROR(INDEX('MMS Alarms - Names'!$F$6:$F$3644,LARGE(('MMS Alarms - Names'!$A$6:$A$3644=$A$5)*(ROW('MMS Alarms - Names'!$A$6:$A$3644)-5),COUNTIF('MMS Alarms - Names'!$A$6:$A$3644,$A$5)+5-ROW('MMS Alarms - Names'!G23))),""),"")} | K23: {=IF($G$4>1,IFERROR(INDEX('MMS Alarms - Names'!$G$6:$G$3644,LARGE(('MMS Alarms - Names'!$A$6:$A$3644=$A$5)*(ROW('MMS Alarms - Names'!$A$6:$A$3644)-5),COUNTIF('MMS Alarms - Names'!$A$6:$A$3644,$A$5)+5-ROW('MMS Alarms - Names'!H23))),""),"")}
B24: =VLOOKUP($A23,'MMS Alarms - Descriptions'!$A$6:$B$3249,2,FALSE) -> #N/A | F24: =VLOOKUP(A23,'MMS Alarms - Names'!$A$6:$G$4233,7,FALSE) -> #N/A | H24: {=IF($G$4>1,IFERROR(INDEX('MMS Alarms - Names'!$A$6:$A$3644,LARGE(('MMS Alarms - Names'!$A$6:$A$3644=$A$5)*(ROW('MMS Alarms - Names'!$A$6:$A$3644)-5),COUNTIF('MMS Alarms - Names'!$A$6:$A$3644,$A$5)+5-ROW('MMS Alarms - Names'!F24))),""),"")} | I24: {=IF($G$4>1,IFERROR(INDEX('MMS Alarms - Names'!$I$6:$I$3644,LARGE(('MMS Alarms - Names'!$A$6:$A$3644=$A$5)*(ROW('MMS Alarms - Names'!$A$6:$A$3644)-5),COUNTIF('MMS Alarms - Names'!$A$6:$A$3644,$A$5)+5-ROW('MMS Alarms - Names'!G24))),""),"")} | J24: {=IF($G$4>1,IFERROR(INDEX('MMS Alarms - Names'!$F$6:$F$3644,LARGE(('MMS Alarms - Names'!$A$6:$A$3644=$A$5)*(ROW('MMS Alarms - Names'!$A$6:$A$3644)-5),COUNTIF('MMS Alarms - Names'!$A$6:$A$3644,$A$5)+5-ROW('MMS Alarms - Names'!G24))),""),"")} | K24: {=IF($G$4>1,IFERROR(INDEX('MMS Alarms - Names'!$G$6:$G$3644,LARGE(('MMS Alarms - Names'!$A$6:$A$3644=$A$5)*(ROW('MMS Alarms - Names'!$A$6:$A$3644)-5),COUNTIF('MMS Alarms - Names'!$A$6:$A$3644,$A$5)+5-ROW('MMS Alarms - Names'!H24))),""),"")}
B25: =VLOOKUP($A25,'MMS Alarms - Names'!$A$6:$B$4233,2,FALSE) -> #N/A | C25: =VLOOKUP($A25,'MMS Alarms - Names'!$A$6:$C$4233,3,FALSE) -> #N/A | D25: =VLOOKUP($A25,'MMS Alarms - Names'!$A$6:$D$4233,4,FALSE) -> #N/A | E25: =VLOOKUP($A25,'MMS Alarms - Names'!$A$6:$E$4233,5,FALSE) -> #N/A | F25: =VLOOKUP(A25,'MMS Alarms - Names'!$A$6:$G$4233,6,FALSE) -> #N/A | H25: {=IF($G$4>1,IFERROR(INDEX('MMS Alarms - Names'!$A$6:$A$3644,LARGE(('MMS Alarms - Names'!$A$6:$A$3644=$A$5)*(ROW('MMS Alarms - Names'!$A$6:$A$3644)-5),COUNTIF('MMS Alarms - Names'!$A$6:$A$3644,$A$5)+5-ROW('MMS Alarms - Names'!F25))),""),"")} | I25: {=IF($G$4>1,IFERROR(INDEX('MMS Alarms - Names'!$I$6:$I$3644,LARGE(('MMS Alarms - Names'!$A$6:$A$3644=$A$5)*(ROW('MMS Alarms - Names'!$A$6:$A$3644)-5),COUNTIF('MMS Alarms - Names'!$A$6:$A$3644,$A$5)+5-ROW('MMS Alarms - Names'!G25))),""),"")} | J25: {=IF($G$4>1,IFERROR(INDEX('MMS Alarms - Names'!$F$6:$F$3644,LARGE(('MMS Alarms - Names'!$A$6:$A$3644=$A$5)*(ROW('MMS Alarms - Names'!$A$6:$A$3644)-5),COUNTIF('MMS Alarms - Names'!$A$6:$A$3644,$A$5)+5-ROW('MMS Alarms - Names'!G25))),""),"")} | K25: {=IF($G$4>1,IFERROR(INDEX('MMS Alarms - Names'!$G$6:$G$3644,LARGE(('MMS Alarms - Names'!$A$6:$A$3644=$A$5)*(ROW('MMS Alarms - Names'!$A$6:$A$3644)-5),COUNTIF('MMS Alarms - Names'!$A$6:$A$3644,$A$5)+5-ROW('MMS Alarms - Names'!H25))),""),"")}
B26: =VLOOKUP($A25,'MMS Alarms - Descriptions'!$A$6:$B$3249,2,FALSE) -> #N/A | F26: =VLOOKUP(A25,'MMS Alarms - Names'!$A$6:$G$4233,7,FALSE) -> #N/A | H26: {=IF($G$4>1,IFERROR(INDEX('MMS Alarms - Names'!$A$6:$A$3644,LARGE(('MMS Alarms - Names'!$A$6:$A$3644=$A$5)*(ROW('MMS Alarms - Names'!$A$6:$A$3644)-5),COUNTIF('MMS Alarms - Names'!$A$6:$A$3644,$A$5)+5-ROW('MMS Alarms - Names'!F26))),""),"")} | I26: {=IF($G$4>1,IFERROR(INDEX('MMS Alarms - Names'!$I$6:$I$3644,LARGE(('MMS Alarms - Names'!$A$6:$A$3644=$A$5)*(ROW('MMS Alarms - Names'!$A$6:$A$3644)-5),COUNTIF('MMS Alarms - Names'!$A$6:$A$3644,$A$5)+5-ROW('MMS Alarms - Names'!G26))),""),"")} | J26: {=IF($G$4>1,IFERROR(INDEX('MMS Alarms - Names'!$F$6:$F$3644,LARGE(('MMS Alarms - Names'!$A$6:$A$3644=$A$5)*(ROW('MMS Alarms - Names'!$A$6:$A$3644)-5),COUNTIF('MMS Alarms - Names'!$A$6:$A$3644,$A$5)+5-ROW('MMS Alarms - Names'!G26))),""),"")} | K26: {=IF($G$4>1,IFERROR(INDEX('MMS Alarms - Names'!$G$6:$G$3644,LARGE(('MMS Alarms - Names'!$A$6:$A$3644=$A$5)*(ROW('MMS Alarms - Names'!$A$6:$A$3644)-5),COUNTIF('MMS Alarms - Names'!$A$6:$A$3644,$A$5)+5-ROW('MMS Alarms - Names'!H26))),""),"")}
B27: =VLOOKUP($A27,'MMS Alarms - Names'!$A$6:$B$4233,2,FALSE) -> #N/A | C27: =VLOOKUP($A27,'MMS Alarms - Names'!$A$6:$C$4233,3,FALSE) -> #N/A | D27: =VLOOKUP($A27,'MMS Alarms - Names'!$A$6:$D$4233,4,FALSE) -> #N/A | E27: =VLOOKUP($A27,'MMS Alarms - Names'!$A$6:$E$4233,5,FALSE) -> #N/A | F27: =VLOOKUP(A27,'MMS Alarms - Names'!$A$6:$G$4233,6,FALSE) -> #N/A | H27: {=IF($G$4>1,IFERROR(INDEX('MMS Alarms - Names'!$A$6:$A$3644,LARGE(('MMS Alarms - Names'!$A$6:$A$3644=$A$5)*(ROW('MMS Alarms - Names'!$A$6:$A$3644)-5),COUNTIF('MMS Alarms - Names'!$A$6:$A$3644,$A$5)+5-ROW('MMS Alarms - Names'!F27))),""),"")} | I27: {=IF($G$4>1,IFERROR(INDEX('MMS Alarms - Names'!$I$6:$I$3644,LARGE(('MMS Alarms - Names'!$A$6:$A$3644=$A$5)*(ROW('MMS Alarms - Names'!$A$6:$A$3644)-5),COUNTIF('MMS Alarms - Names'!$A$6:$A$3644,$A$5)+5-ROW('MMS Alarms - Names'!G27))),""),"")} | J27: {=IF($G$4>1,IFERROR(INDEX('MMS Alarms - Names'!$F$6:$F$3644,LARGE(('MMS Alarms - Names'!$A$6:$A$3644=$A$5)*(ROW('MMS Alarms - Names'!$A$6:$A$3644)-5),COUNTIF('MMS Alarms - Names'!$A$6:$A$3644,$A$5)+5-ROW('MMS Alarms - Names'!G27))),""),"")} | K27: {=IF($G$4>1,IFERROR(INDEX('MMS Alarms - Names'!$G$6:$G$3644,LARGE(('MMS Alarms - Names'!$A$6:$A$3644=$A$5)*(ROW('MMS Alarms - Names'!$A$6:$A$3644)-5),COUNTIF('MMS Alarms - Names'!$A$6:$A$3644,$A$5)+5-ROW('MMS Alarms - Names'!H27))),""),"")}
B28: =VLOOKUP($A27,'MMS Alarms - Descriptions'!$A$6:$B$3249,2,FALSE) -> #N/A | F28: =VLOOKUP(A27,'MMS Alarms - Names'!$A$6:$G$4233,7,FALSE) -> #N/A | H28: {=IF($G$4>1,IFERROR(INDEX('MMS Alarms - Names'!$A$6:$A$3644,LARGE(('MMS Alarms - Names'!$A$6:$A$3644=$A$5)*(ROW('MMS Alarms - Names'!$A$6:$A$3644)-5),COUNTIF('MMS Alarms - Names'!$A$6:$A$3644,$A$5)+5-ROW('MMS Alarms - Names'!F28))),""),"")} | I28: {=IF($G$4>1,IFERROR(INDEX('MMS Alarms - Names'!$I$6:$I$3644,LARGE(('MMS Alarms - Names'!$A$6:$A$3644=$A$5)*(ROW('MMS Alarms - Names'!$A$6:$A$3644)-5),COUNTIF('MMS Alarms - Names'!$A$6:$A$3644,$A$5)+5-ROW('MMS Alarms - Names'!G28))),""),"")} | J28: {=IF($G$4>1,IFERROR(INDEX('MMS Alarms - Names'!$F$6:$F$3644,LARGE(('MMS Alarms - Names'!$A$6:$A$3644=$A$5)*(ROW('MMS Alarms - Names'!$A$6:$A$3644)-5),COUNTIF('MMS Alarms - Names'!$A$6:$A$3644,$A$5)+5-ROW('MMS Alarms - Names'!G28))),""),"")} | K28: {=IF($G$4>1,IFERROR(INDEX('MMS Alarms - Names'!$G$6:$G$3644,LARGE(('MMS Alarms - Names'!$A$6:$A$3644=$A$5)*(ROW('MMS Alarms - Names'!$A$6:$A$3644)-5),COUNTIF('MMS Alarms - Names'!$A$6:$A$3644,$A$5)+5-ROW('MMS Alarms - Names'!H28))),""),"")}
B29: =VLOOKUP($A29,'MMS Alarms - Names'!$A$6:$B$4233,2,FALSE) -> #N/A | C29: =VLOOKUP($A29,'MMS Alarms - Names'!$A$6:$C$4233,3,FALSE) -> #N/A | D29: =VLOOKUP($A29,'MMS Alarms - Names'!$A$6:$D$4233,4,FALSE) -> #N/A | E29: =VLOOKUP($A29,'MMS Alarms - Names'!$A$6:$E$4233,5,FALSE) -> #N/A | F29: =VLOOKUP(A29,'MMS Alarms - Names'!$A$6:$G$4233,6,FALSE) -> #N/A | H29: {=IF($G$4>1,IFERROR(INDEX('MMS Alarms - Names'!$A$6:$A$3644,LARGE(('MMS Alarms - Names'!$A$6:$A$3644=$A$5)*(ROW('MMS Alarms - Names'!$A$6:$A$3644)-5),COUNTIF('MMS Alarms - Names'!$A$6:$A$3644,$A$5)+5-ROW('MMS Alarms - Names'!F29))),""),"")} | I29: {=IF($G$4>1,IFERROR(INDEX('MMS Alarms - Names'!$I$6:$I$3644,LARGE(('MMS Alarms - Names'!$A$6:$A$3644=$A$5)*(ROW('MMS Alarms - Names'!$A$6:$A$3644)-5),COUNTIF('MMS Alarms - Names'!$A$6:$A$3644,$A$5)+5-ROW('MMS Alarms - Names'!G29))),""),"")} | J29: {=IF($G$4>1,IFERROR(INDEX('MMS Alarms - Names'!$F$6:$F$3644,LARGE(('MMS Alarms - Names'!$A$6:$A$3644=$A$5)*(ROW('MMS Alarms - Names'!$A$6:$A$3644)-5),COUNTIF('MMS Alarms - Names'!$A$6:$A$3644,$A$5)+5-ROW('MMS Alarms - Names'!G29))),""),"")} | K29: {=IF($G$4>1,IFERROR(INDEX('MMS Alarms - Names'!$G$6:$G$3644,LARGE(('MMS Alarms - Names'!$A$6:$A$3644=$A$5)*(ROW('MMS Alarms - Names'!$A$6:$A$3644)-5),COUNTIF('MMS Alarms - Names'!$A$6:$A$3644,$A$5)+5-ROW('MMS Alarms - Names'!H29))),""),"")}
B30: =VLOOKUP($A29,'MMS Alarms - Descriptions'!$A$6:$B$3249,2,FALSE) -> #N/A | F30: =VLOOKUP(A29,'MMS Alarms - Names'!$A$6:$G$4233,7,FALSE) -> #N/A | H30: {=IF($G$4>1,IFERROR(INDEX('MMS Alarms - Names'!$A$6:$A$3644,LARGE(('MMS Alarms - Names'!$A$6:$A$3644=$A$5)*(ROW('MMS Alarms - Names'!$A$6:$A$3644)-5),COUNTIF('MMS Alarms - Names'!$A$6:$A$3644,$A$5)+5-ROW('MMS Alarms - Names'!F30))),""),"")} | I30: {=IF($G$4>1,IFERROR(INDEX('MMS Alarms - Names'!$I$6:$I$3644,LARGE(('MMS Alarms - Names'!$A$6:$A$3644=$A$5)*(ROW('MMS Alarms - Names'!$A$6:$A$3644)-5),COUNTIF('MMS Alarms - Names'!$A$6:$A$3644,$A$5)+5-ROW('MMS Alarms - Names'!G30))),""),"")} | J30: {=IF($G$4>1,IFERROR(INDEX('MMS Alarms - Names'!$F$6:$F$3644,LARGE(('MMS Alarms - Names'!$A$6:$A$3644=$A$5)*(ROW('MMS Alarms - Names'!$A$6:$A$3644)-5),COUNTIF('MMS Alarms - Names'!$A$6:$A$3644,$A$5)+5-ROW('MMS Alarms - Names'!G30))),""),"")} | K30: {=IF($G$4>1,IFERROR(INDEX('MMS Alarms - Names'!$G$6:$G$3644,LARGE(('MMS Alarms - Names'!$A$6:$A$3644=$A$5)*(ROW('MMS Alarms - Names'!$A$6:$A$3644)-5),COUNTIF('MMS Alarms - Names'!$A$6:$A$3644,$A$5)+5-ROW('MMS Alarms - Names'!H30))),""),"")}
H31: {=IF($G$4>1,IFERROR(INDEX('MMS Alarms - Names'!$A$6:$A$3644,LARGE(('MMS Alarms - Names'!$A$6:$A$3644=$A$5)*(ROW('MMS Alarms - Names'!$A$6:$A$3644)-5),COUNTIF('MMS Alarms - Names'!$A$6:$A$3644,$A$5)+5-ROW('MMS Alarms - Names'!F31))),""),"")} | I31: {=IF($G$4>1,IFERROR(INDEX('MMS Alarms - Names'!$I$6:$I$3644,LARGE(('MMS Alarms - Names'!$A$6:$A$3644=$A$5)*(ROW('MMS Alarms - Names'!$A$6:$A$3644)-5),COUNTIF('MMS Alarms - Names'!$A$6:$A$3644,$A$5)+5-ROW('MMS Alarms - Names'!G31))),""),"")} | J31: {=IF($G$4>1,IFERROR(INDEX('MMS Alarms - Names'!$F$6:$F$3644,LARGE(('MMS Alarms - Names'!$A$6:$A$3644=$A$5)*(ROW('MMS Alarms - Names'!$A$6:$A$3644)-5),COUNTIF('MMS Alarms - Names'!$A$6:$A$3644,$A$5)+5-ROW('MMS Alarms - Names'!G31))),""),"")} | K31: {=IF($G$4>1,IFERROR(INDEX('MMS Alarms - Names'!$G$6:$G$3644,LARGE(('MMS Alarms - Names'!$A$6:$A$3644=$A$5)*(ROW('MMS Alarms - Names'!$A$6:$A$3644)-5),COUNTIF('MMS Alarms - Names'!$A$6:$A$3644,$A$5)+5-ROW('MMS Alarms - Names'!H31))),""),"")}
H32: {=IF($G$4>1,IFERROR(INDEX('MMS Alarms - Names'!$A$6:$A$3644,LARGE(('MMS Alarms - Names'!$A$6:$A$3644=$A$5)*(ROW('MMS Alarms - Names'!$A$6:$A$3644)-5),COUNTIF('MMS Alarms - Names'!$A$6:$A$3644,$A$5)+5-ROW('MMS Alarms - Names'!F32))),""),"")} | I32: {=IF($G$4>1,IFERROR(INDEX('MMS Alarms - Names'!$I$6:$I$3644,LARGE(('MMS Alarms - Names'!$A$6:$A$3644=$A$5)*(ROW('MMS Alarms - Names'!$A$6:$A$3644)-5),COUNTIF('MMS Alarms - Names'!$A$6:$A$3644,$A$5)+5-ROW('MMS Alarms - Names'!G32))),""),"")} | J32: {=IF($G$4>1,IFERROR(INDEX('MMS Alarms - Names'!$F$6:$F$3644,LARGE(('MMS Alarms - Names'!$A$6:$A$3644=$A$5)*(ROW('MMS Alarms - Names'!$A$6:$A$3644)-5),COUNTIF('MMS Alarms - Names'!$A$6:$A$3644,$A$5)+5-ROW('MMS Alarms - Names'!G32))),""),"")} | K32: {=IF($G$4>1,IFERROR(INDEX('MMS Alarms - Names'!$G$6:$G$3644,LARGE(('MMS Alarms - Names'!$A$6:$A$3644=$A$5)*(ROW('MMS Alarms - Names'!$A$6:$A$3644)-5),COUNTIF('MMS Alarms - Names'!$A$6:$A$3644,$A$5)+5-ROW('MMS Alarms - Names'!H32))),""),"")}
H33: {=IF($G$4>1,IFERROR(INDEX('MMS Alarms - Names'!$A$6:$A$3644,LARGE(('MMS Alarms - Names'!$A$6:$A$3644=$A$5)*(ROW('MMS Alarms - Names'!$A$6:$A$3644)-5),COUNTIF('MMS Alarms - Names'!$A$6:$A$3644,$A$5)+5-ROW('MMS Alarms - Names'!F33))),""),"")} | I33: {=IF($G$4>1,IFERROR(INDEX('MMS Alarms - Names'!$I$6:$I$3644,LARGE(('MMS Alarms - Names'!$A$6:$A$3644=$A$5)*(ROW('MMS Alarms - Names'!$A$6:$A$3644)-5),COUNTIF('MMS Alarms - Names'!$A$6:$A$3644,$A$5)+5-ROW('MMS Alarms - Names'!G33))),""),"")} | J33: {=IF($G$4>1,IFERROR(INDEX('MMS Alarms - Names'!$F$6:$F$3644,LARGE(('MMS Alarms - Names'!$A$6:$A$3644=$A$5)*(ROW('MMS Alarms - Names'!$A$6:$A$3644)-5),COUNTIF('MMS Alarms - Names'!$A$6:$A$3644,$A$5)+5-ROW('MMS Alarms - Names'!G33))),""),"")} | K33: {=IF($G$4>1,IFERROR(INDEX('MMS Alarms - Names'!$G$6:$G$3644,LARGE(('MMS Alarms - Names'!$A$6:$A$3644=$A$5)*(ROW('MMS Alarms - Names'!$A$6:$A$3644)-5),COUNTIF('MMS Alarms - Names'!$A$6:$A$3644,$A$5)+5-ROW('MMS Alarms - Names'!H33))),""),"")}
H34: {=IF($G$4>1,IFERROR(INDEX('MMS Alarms - Names'!$A$6:$A$3644,LARGE(('MMS Alarms - Names'!$A$6:$A$3644=$A$5)*(ROW('MMS Alarms - Names'!$A$6:$A$3644)-5),COUNTIF('MMS Alarms - Names'!$A$6:$A$3644,$A$5)+5-ROW('MMS Alarms - Names'!F34))),""),"")} | I34: {=IF($G$4>1,IFERROR(INDEX('MMS Alarms - Names'!$I$6:$I$3644,LARGE(('MMS Alarms - Names'!$A$6:$A$3644=$A$5)*(ROW('MMS Alarms - Names'!$A$6:$A$3644)-5),COUNTIF('MMS Alarms - Names'!$A$6:$A$3644,$A$5)+5-ROW('MMS Alarms - Names'!G34))),""),"")} | J34: {=IF($G$4>1,IFERROR(INDEX('MMS Alarms - Names'!$F$6:$F$3644,LARGE(('MMS Alarms - Names'!$A$6:$A$3644=$A$5)*(ROW('MMS Alarms - Names'!$A$6:$A$3644)-5),COUNTIF('MMS Alarms - Names'!$A$6:$A$3644,$A$5)+5-ROW('MMS Alarms - Names'!G34))),""),"")} | K34: {=IF($G$4>1,IFERROR(INDEX('MMS Alarms - Names'!$G$6:$G$3644,LARGE(('MMS Alarms - Names'!$A$6:$A$3644=$A$5)*(ROW('MMS Alarms - Names'!$A$6:$A$3644)-5),COUNTIF('MMS Alarms - Names'!$A$6:$A$3644,$A$5)+5-ROW('MMS Alarms - Names'!H34))),""),"")}
H35: {=IF($G$4>1,IFERROR(INDEX('MMS Alarms - Names'!$A$6:$A$3644,LARGE(('MMS Alarms - Names'!$A$6:$A$3644=$A$5)*(ROW('MMS Alarms - Names'!$A$6:$A$3644)-5),COUNTIF('MMS Alarms - Names'!$A$6:$A$3644,$A$5)+5-ROW('MMS Alarms - Names'!F35))),""),"")} | I35: {=IF($G$4>1,IFERROR(INDEX('MMS Alarms - Names'!$I$6:$I$3644,LARGE(('MMS Alarms - Names'!$A$6:$A$3644=$A$5)*(ROW('MMS Alarms - Names'!$A$6:$A$3644)-5),COUNTIF('MMS Alarms - Names'!$A$6:$A$3644,$A$5)+5-ROW('MMS Alarms - Names'!G35))),""),"")} | J35: {=IF($G$4>1,IFERROR(INDEX('MMS Alarms - Names'!$F$6:$F$3644,LARGE(('MMS Alarms - Names'!$A$6:$A$3644=$A$5)*(ROW('MMS Alarms - Names'!$A$6:$A$3644)-5),COUNTIF('MMS Alarms - Names'!$A$6:$A$3644,$A$5)+5-ROW('MMS Alarms - Names'!G35))),""),"")} | K35: {=IF($G$4>1,IFERROR(INDEX('MMS Alarms - Names'!$G$6:$G$3644,LARGE(('MMS Alarms - Names'!$A$6:$A$3644=$A$5)*(ROW('MMS Alarms - Names'!$A$6:$A$3644)-5),COUNTIF('MMS Alarms - Names'!$A$6:$A$3644,$A$5)+5-ROW('MMS Alarms - Names'!H35))),""),"")}
H36: {=IF($G$4>1,IFERROR(INDEX('MMS Alarms - Names'!$A$6:$A$3644,LARGE(('MMS Alarms - Names'!$A$6:$A$3644=$A$5)*(ROW('MMS Alarms - Names'!$A$6:$A$3644)-5),COUNTIF('MMS Alarms - Names'!$A$6:$A$3644,$A$5)+5-ROW('MMS Alarms - Names'!F36))),""),"")} | I36: {=IF($G$4>1,IFERROR(INDEX('MMS Alarms - Names'!$I$6:$I$3644,LARGE(('MMS Alarms - Names'!$A$6:$A$3644=$A$5)*(ROW('MMS Alarms - Names'!$A$6:$A$3644)-5),COUNTIF('MMS Alarms - Names'!$A$6:$A$3644,$A$5)+5-ROW('MMS Alarms - Names'!G36))),""),"")} | J36: {=IF($G$4>1,IFERROR(INDEX('MMS Alarms - Names'!$F$6:$F$3644,LARGE(('MMS Alarms - Names'!$A$6:$A$3644=$A$5)*(ROW('MMS Alarms - Names'!$A$6:$A$3644)-5),COUNTIF('MMS Alarms - Names'!$A$6:$A$3644,$A$5)+5-ROW('MMS Alarms - Names'!G36))),""),"")} | K36: {=IF($G$4>1,IFERROR(INDEX('MMS Alarms - Names'!$G$6:$G$3644,LARGE(('MMS Alarms - Names'!$A$6:$A$3644=$A$5)*(ROW('MMS Alarms - Names'!$A$6:$A$3644)-5),COUNTIF('MMS Alarms - Names'!$A$6:$A$3644,$A$5)+5-ROW('MMS Alarms - Names'!H36))),""),"")}
H37: {=IF($G$4>1,IFERROR(INDEX('MMS Alarms - Names'!$A$6:$A$3644,LARGE(('MMS Alarms - Names'!$A$6:$A$3644=$A$5)*(ROW('MMS Alarms - Names'!$A$6:$A$3644)-5),COUNTIF('MMS Alarms - Names'!$A$6:$A$3644,$A$5)+5-ROW('MMS Alarms - Names'!F37))),""),"")} | I37: {=IF($G$4>1,IFERROR(INDEX('MMS Alarms - Names'!$I$6:$I$3644,LARGE(('MMS Alarms - Names'!$A$6:$A$3644=$A$5)*(ROW('MMS Alarms - Names'!$A$6:$A$3644)-5),COUNTIF('MMS Alarms - Names'!$A$6:$A$3644,$A$5)+5-ROW('MMS Alarms - Names'!G37))),""),"")} | J37: {=IF($G$4>1,IFERROR(INDEX('MMS Alarms - Names'!$F$6:$F$3644,LARGE(('MMS Alarms - Names'!$A$6:$A$3644=$A$5)*(ROW('MMS Alarms - Names'!$A$6:$A$3644)-5),COUNTIF('MMS Alarms - Names'!$A$6:$A$3644,$A$5)+5-ROW('MMS Alarms - Names'!G37))),""),"")} | K37: {=IF($G$4>1,IFERROR(INDEX('MMS Alarms - Names'!$G$6:$G$3644,LARGE(('MMS Alarms - Names'!$A$6:$A$3644=$A$5)*(ROW('MMS Alarms - Names'!$A$6:$A$3644)-5),COUNTIF('MMS Alarms - Names'!$A$6:$A$3644,$A$5)+5-ROW('MMS Alarms - Names'!H37))),""),"")}

Sheet SPN Suche - SPN Search
A1: Suche nach SPN || Search for SPN
A2: Schreibe die gesuchten SPN in SpalteSPN => Die zur SPN gehörenden Alarm Informationen werden rechts daneben angezeigt. Wird eine SPN nicht gefunden, so bleibt die Zeile leer. Fill in the SPN you are looking for into column SPN => Error code information is displayed in the cells on the right. If the SPN could not be found then the line will be empty.
A3: SPN | B3: Error Code(s) | C3: PR ZKP | D3: PV ZKP | E3: Name (English) | F3: Name (Deutsch) | G3: SPN | H3: FMI | I3: Description
B4: {=IFERROR(INDEX('MMS Alarms - Names'!$A$6:$A$3873,LARGE(('MMS Alarms - Names'!$F$6:$F$3873=$A$4)*(ROW('MMS Alarms - Names'!$F$6:$F$3873)-5),COUNTIF('MMS Alarms - Names'!$F$6:$F$3873,$A$4)+5-ROW('MMS Alarms - Names'!F5))),"")} | C4: =IFERROR(VLOOKUP($B4,'MMS Alarms - Names'!$A$6:$B$4233,2,FALSE),"") | D4: =IFERROR(VLOOKUP($B4,'MMS Alarms - Names'!$A$6:$C$4233,3,FALSE),"") | E4: =IFERROR(VLOOKUP($B4,'MMS Alarms - Names'!$A$6:$D$4233,4,FALSE),"") | F4: =IFERROR(VLOOKUP($B4,'MMS Alarms - Names'!$A$6:$E$4233,5,FALSE),"") | G4: =IFERROR(VLOOKUP(B4,'MMS Alarms - Names'!$A$6:$G$4233,6,FALSE),"") | H4: =IFERROR(VLOOKUP(B4,'MMS Alarms - Names'!$A$6:$G$4233,7,FALSE),"") | I4: =IFERROR(VLOOKUP($B4,'MMS Alarms - Descriptions'!$A$6:$B$3249,2,FALSE),"")
B5: {=IFERROR(INDEX('MMS Alarms - Names'!$A$6:$A$3873,LARGE(('MMS Alarms - Names'!$F$6:$F$3873=$A$4)*(ROW('MMS Alarms - Names'!$F$6:$F$3873)-5),COUNTIF('MMS Alarms - Names'!$F$6:$F$3873,$A$4)+5-ROW('MMS Alarms - Names'!F6))),"")} | C5: =IFERROR(VLOOKUP($B5,'MMS Alarms - Names'!$A$6:$B$4233,2,FALSE),"") | D5: =IFERROR(VLOOKUP($B5,'MMS Alarms - Names'!$A$6:$C$4233,3,FALSE),"") | E5: =IFERROR(VLOOKUP($B5,'MMS Alarms - Names'!$A$6:$D$4233,4,FALSE),"") | F5: =IFERROR(VLOOKUP($B5,'MMS Alarms - Names'!$A$6:$E$4233,5,FALSE),"") | G5: =IFERROR(VLOOKUP(B5,'MMS Alarms - Names'!$A$6:$G$4233,6,FALSE),"") | H5: =IFERROR(VLOOKUP(B5,'MMS Alarms - Names'!$A$6:$G$4233,7,FALSE),"") | I5: =IFERROR(VLOOKUP($B5,'MMS Alarms - Descriptions'!$A$6:$B$3249,2,FALSE),"")
B6: {=IFERROR(INDEX('MMS Alarms - Names'!$A$6:$A$3873,LARGE(('MMS Alarms - Names'!$F$6:$F$3873=$A$4)*(ROW('MMS Alarms - Names'!$F$6:$F$3873)-5),COUNTIF('MMS Alarms - Names'!$F$6:$F$3873,$A$4)+5-ROW('MMS Alarms - Names'!F7))),"")} | C6: =IFERROR(VLOOKUP($B6,'MMS Alarms - Names'!$A$6:$B$4233,2,FALSE),"") | D6: =IFERROR(VLOOKUP($B6,'MMS Alarms - Names'!$A$6:$C$4233,3,FALSE),"") | E6: =IFERROR(VLOOKUP($B6,'MMS Alarms - Names'!$A$6:$D$4233,4,FALSE),"") | F6: =IFERROR(VLOOKUP($B6,'MMS Alarms - Names'!$A$6:$E$4233,5,FALSE),"") | G6: =IFERROR(VLOOKUP(B6,'MMS Alarms - Names'!$A$6:$G$4233,6,FALSE),"") | H6: =IFERROR(VLOOKUP(B6,'MMS Alarms - Names'!$A$6:$G$4233,7,FALSE),"") | I6: =IFERROR(VLOOKUP($B6,'MMS Alarms - Descriptions'!$A$6:$B$3249,2,FALSE),"")
B7: {=IFERROR(INDEX('MMS Alarms - Names'!$A$6:$A$3873,LARGE(('MMS Alarms - Names'!$F$6:$F$3873=$A$4)*(ROW('MMS Alarms - Names'!$F$6:$F$3873)-5),COUNTIF('MMS Alarms - Names'!$F$6:$F$3873,$A$4)+5-ROW('MMS Alarms - Names'!F8))),"")} | C7: =IFERROR(VLOOKUP($B7,'MMS Alarms - Names'!$A$6:$B$4233,2,FALSE),"") | D7: =IFERROR(VLOOKUP($B7,'MMS Alarms - Names'!$A$6:$C$4233,3,FALSE),"") | E7: =IFERROR(VLOOKUP($B7,'MMS Alarms - Names'!$A$6:$D$4233,4,FALSE),"") | F7: =IFERROR(VLOOKUP($B7,'MMS Alarms - Names'!$A$6:$E$4233,5,FALSE),"") | G7: =IFERROR(VLOOKUP(B7,'MMS Alarms - Names'!$A$6:$G$4233,6,FALSE),"") | H7: =IFERROR(VLOOKUP(B7,'MMS Alarms - Names'!$A$6:$G$4233,7,FALSE),"") | I7: =IFERROR(VLOOKUP($B7,'MMS Alarms - Descriptions'!$A$6:$B$3249,2,FALSE),"")
B8: {=IFERROR(INDEX('MMS Alarms - Names'!$A$6:$A$3873,LARGE(('MMS Alarms - Names'!$F$6:$F$3873=$A$4)*(ROW('MMS Alarms - Names'!$F$6:$F$3873)-5),COUNTIF('MMS Alarms - Names'!$F$6:$F$3873,$A$4)+5-ROW('MMS Alarms - Names'!F9))),"")} | C8: =IFERROR(VLOOKUP($B8,'MMS Alarms - Names'!$A$6:$B$4233,2,FALSE),"") | D8: =IFERROR(VLOOKUP($B8,'MMS Alarms - Names'!$A$6:$C$4233,3,FALSE),"") | E8: =IFERROR(VLOOKUP($B8,'MMS Alarms - Names'!$A$6:$D$4233,4,FALSE),"") | F8: =IFERROR(VLOOKUP($B8,'MMS Alarms - Names'!$A$6:$E$4233,5,FALSE),"") | G8: =IFERROR(VLOOKUP(B8,'MMS Alarms - Names'!$A$6:$G$4233,6,FALSE),"") | H8: =IFERROR(VLOOKUP(B8,'MMS Alarms - Names'!$A$6:$G$4233,7,FALSE),"") | I8: =IFERROR(VLOOKUP($B8,'MMS Alarms - Descriptions'!$A$6:$B$3249,2,FALSE),"")
B9: {=IFERROR(INDEX('MMS Alarms - Names'!$A$6:$A$3873,LARGE(('MMS Alarms - Names'!$F$6:$F$3873=$A$4)*(ROW('MMS Alarms - Names'!$F$6:$F$3873)-5),COUNTIF('MMS Alarms - Names'!$F$6:$F$3873,$A$4)+5-ROW('MMS Alarms - Names'!F10))),"")} | C9: =IFERROR(VLOOKUP($B9,'MMS Alarms - Names'!$A$6:$B$4233,2,FALSE),"") | D9: =IFERROR(VLOOKUP($B9,'MMS Alarms - Names'!$A$6:$C$4233,3,FALSE),"") | E9: =IFERROR(VLOOKUP($B9,'MMS Alarms - Names'!$A$6:$D$4233,4,FALSE),"") | F9: =IFERROR(VLOOKUP($B9,'MMS Alarms - Names'!$A$6:$E$4233,5,FALSE),"") | G9: =IFERROR(VLOOKUP(B9,'MMS Alarms - Names'!$A$6:$G$4233,6,FALSE),"") | H9: =IFERROR(VLOOKUP(B9,'MMS Alarms - Names'!$A$6:$G$4233,7,FALSE),"") | I9: =IFERROR(VLOOKUP($B9,'MMS Alarms - Descriptions'!$A$6:$B$3249,2,FALSE),"")
